[2025-03-12T13:24:58.040+0000] {local_task_job_runner.py:123} INFO - ::group::Pre task execution logs
[2025-03-12T13:24:58.068+0000] {taskinstance.py:2614} INFO - Dependencies all met for dep_context=non-requeueable deps ti=<TaskInstance: data_lake_pipeline.process_to_raw manual__2025-03-12T13:24:50.960714+00:00 [queued]>
[2025-03-12T13:24:58.081+0000] {taskinstance.py:2614} INFO - Dependencies all met for dep_context=requeueable deps ti=<TaskInstance: data_lake_pipeline.process_to_raw manual__2025-03-12T13:24:50.960714+00:00 [queued]>
[2025-03-12T13:24:58.081+0000] {taskinstance.py:2867} INFO - Starting attempt 1 of 2
[2025-03-12T13:24:58.108+0000] {taskinstance.py:2890} INFO - Executing <Task(PythonOperator): process_to_raw> on 2025-03-12 13:24:50.960714+00:00
[2025-03-12T13:24:58.114+0000] {standard_task_runner.py:72} INFO - Started process 219 to run task
[2025-03-12T13:24:58.118+0000] {standard_task_runner.py:104} INFO - Running: ['***', 'tasks', 'run', 'data_lake_pipeline', 'process_to_raw', 'manual__2025-03-12T13:24:50.960714+00:00', '--job-id', '36', '--raw', '--subdir', 'DAGS_FOLDER/data_pipeline_dag.py', '--cfg-path', '/tmp/tmpmrqwkbex']
[2025-03-12T13:24:58.121+0000] {standard_task_runner.py:105} INFO - Job 36: Subtask process_to_raw
[2025-03-12T13:24:58.138+0000] {logging_mixin.py:190} WARNING - /usr/local/lib/python3.10/site-packages/***/settings.py:209 DeprecationWarning: The sql_alchemy_conn option in [core] has been moved to the sql_alchemy_conn option in [database] - the old setting has been used, but please update your config.
[2025-03-12T13:24:58.181+0000] {task_command.py:467} INFO - Running <TaskInstance: data_lake_pipeline.process_to_raw manual__2025-03-12T13:24:50.960714+00:00 [running]> on host ***-scheduler
[2025-03-12T13:24:58.289+0000] {taskinstance.py:3134} INFO - Exporting env vars: AIRFLOW_CTX_DAG_OWNER='***' AIRFLOW_CTX_DAG_ID='data_lake_pipeline' AIRFLOW_CTX_TASK_ID='process_to_raw' AIRFLOW_CTX_EXECUTION_DATE='2025-03-12T13:24:50.960714+00:00' AIRFLOW_CTX_TRY_NUMBER='1' AIRFLOW_CTX_DAG_RUN_ID='manual__2025-03-12T13:24:50.960714+00:00'
[2025-03-12T13:24:58.290+0000] {taskinstance.py:732} INFO - ::endgroup::
[2025-03-12T13:24:58.305+0000] {manage_buckets.py:19} INFO - [Data manager] Downloading data from HuggingFace...
[2025-03-12T13:25:09.893+0000] {logging_mixin.py:190} WARNING - Generating test split:   0%|          | 0/4358 [00:00<?, ? examples/s]
[2025-03-12T13:25:09.917+0000] {logging_mixin.py:190} WARNING - Generating test split: 100%|##########| 4358/4358 [00:00<00:00, 183187.12 examples/s]
[2025-03-12T13:25:09.918+0000] {logging_mixin.py:190} WARNING - Generating train split:   0%|          | 0/36718 [00:00<?, ? examples/s]
[2025-03-12T13:25:09.959+0000] {logging_mixin.py:190} WARNING - Generating train split: 100%|##########| 36718/36718 [00:00<00:00, 929457.46 examples/s]
[2025-03-12T13:25:09.960+0000] {logging_mixin.py:190} WARNING - Generating validation split:   0%|          | 0/3760 [00:00<?, ? examples/s]
[2025-03-12T13:25:09.968+0000] {logging_mixin.py:190} WARNING - Generating validation split: 100%|##########| 3760/3760 [00:00<00:00, 468762.69 examples/s]
[2025-03-12T13:25:09.984+0000] {manage_buckets.py:22} INFO - [Data manager] Data successfully downloaded.
[2025-03-12T13:25:09.985+0000] {manage_buckets.py:25} INFO - [Data manager] Transferring data to S3 bucket...
[2025-03-12T13:25:09.985+0000] {aws_s3_repository.py:65} INFO - [AWS S3] ðŸš€ Uploading into raw ...
[2025-03-12T13:25:09.985+0000] {aws_s3_repository.py:68} INFO - [AWS S3] Transferring train data...
[2025-03-12T13:25:09.986+0000] {aws_s3_repository.py:69} INFO - [AWS S3] split_data: Dataset({
    features: ['text'],
    num_rows: 36718
})
[2025-03-12T13:25:10.069+0000] {aws_s3_repository.py:71} INFO - [AWS S3] Unit: 
[2025-03-12T13:25:10.079+0000] {aws_s3_repository.py:77} INFO - [AWS S3] Uploading ... to train/train_0.txt
[2025-03-12T13:25:10.420+0000] {aws_s3.py:36} CRITICAL - [S3 Client] Error : An error occurred (InvalidAccessKeyId) when calling the PutObject operation: The AWS Access Key Id you provided does not exist in our records.
[2025-03-12T13:25:10.424+0000] {aws_s3_repository.py:82} CRITICAL - [AWS S3] Error while uploading data into raw ...
[2025-03-12T13:25:10.424+0000] {manage_buckets.py:37} CRITICAL - [Data manager] Error during uploading files to S3 bucket named raw
[2025-03-12T13:25:10.425+0000] {python.py:240} INFO - Done. Returned value was: None
[2025-03-12T13:25:10.440+0000] {taskinstance.py:341} INFO - ::group::Post task execution logs
[2025-03-12T13:25:10.440+0000] {taskinstance.py:353} INFO - Marking task as SUCCESS. dag_id=data_lake_pipeline, task_id=process_to_raw, run_id=manual__2025-03-12T13:24:50.960714+00:00, execution_date=20250312T132450, start_date=20250312T132458, end_date=20250312T132510
[2025-03-12T13:25:10.504+0000] {local_task_job_runner.py:266} INFO - Task exited with return code 0
[2025-03-12T13:25:10.523+0000] {taskinstance.py:3901} INFO - 0 downstream tasks scheduled from follow-on schedule check
[2025-03-12T13:25:10.527+0000] {local_task_job_runner.py:245} INFO - ::endgroup::
