[2025-03-12T21:28:51.105+0000] {local_task_job_runner.py:123} INFO - ::group::Pre task execution logs
[2025-03-12T21:28:51.148+0000] {taskinstance.py:2614} INFO - Dependencies all met for dep_context=non-requeueable deps ti=<TaskInstance: data_lake_pipeline.transform_staging_to_curated manual__2025-03-12T21:17:19.069606+00:00 [queued]>
[2025-03-12T21:28:51.167+0000] {taskinstance.py:2614} INFO - Dependencies all met for dep_context=requeueable deps ti=<TaskInstance: data_lake_pipeline.transform_staging_to_curated manual__2025-03-12T21:17:19.069606+00:00 [queued]>
[2025-03-12T21:28:51.168+0000] {taskinstance.py:2867} INFO - Starting attempt 2 of 2
[2025-03-12T21:28:51.200+0000] {taskinstance.py:2890} INFO - Executing <Task(PythonOperator): transform_staging_to_curated> on 2025-03-12 21:17:19.069606+00:00
[2025-03-12T21:28:51.215+0000] {standard_task_runner.py:72} INFO - Started process 173 to run task
[2025-03-12T21:28:51.231+0000] {standard_task_runner.py:104} INFO - Running: ['***', 'tasks', 'run', 'data_lake_pipeline', 'transform_staging_to_curated', 'manual__2025-03-12T21:17:19.069606+00:00', '--job-id', '49', '--raw', '--subdir', 'DAGS_FOLDER/data_pipeline_dag.py', '--cfg-path', '/tmp/tmpjc0k1y9b']
[2025-03-12T21:28:51.234+0000] {standard_task_runner.py:105} INFO - Job 49: Subtask transform_staging_to_curated
[2025-03-12T21:28:51.269+0000] {logging_mixin.py:190} WARNING - /usr/local/lib/python3.10/site-packages/***/settings.py:209 DeprecationWarning: The sql_alchemy_conn option in [core] has been moved to the sql_alchemy_conn option in [database] - the old setting has been used, but please update your config.
[2025-03-12T21:28:51.342+0000] {task_command.py:467} INFO - Running <TaskInstance: data_lake_pipeline.transform_staging_to_curated manual__2025-03-12T21:17:19.069606+00:00 [running]> on host ***-scheduler
[2025-03-12T21:28:51.510+0000] {taskinstance.py:3134} INFO - Exporting env vars: AIRFLOW_CTX_DAG_OWNER='***' AIRFLOW_CTX_DAG_ID='data_lake_pipeline' AIRFLOW_CTX_TASK_ID='transform_staging_to_curated' AIRFLOW_CTX_EXECUTION_DATE='2025-03-12T21:17:19.069606+00:00' AIRFLOW_CTX_TRY_NUMBER='2' AIRFLOW_CTX_DAG_RUN_ID='manual__2025-03-12T21:17:19.069606+00:00'
[2025-03-12T21:28:51.513+0000] {taskinstance.py:732} INFO - ::endgroup::
[2025-03-12T21:28:51.541+0000] {manage_buckets.py:63} INFO - [Data manager] Prefix(s) : ['test', 'train', 'validation']
[2025-03-12T21:28:51.542+0000] {manage_buckets.py:66} INFO - [Data manager] Processing data from: test
[2025-03-12T21:28:51.543+0000] {taskinstance.py:3313} ERROR - Task failed with exception
Traceback (most recent call last):
  File "/usr/local/lib/python3.10/site-packages/airflow/models/taskinstance.py", line 768, in _execute_task
    result = _execute_callable(context=context, **execute_callable_kwargs)
  File "/usr/local/lib/python3.10/site-packages/airflow/models/taskinstance.py", line 734, in _execute_callable
    return ExecutionCallableRunner(
  File "/usr/local/lib/python3.10/site-packages/airflow/utils/operator_helpers.py", line 252, in run
    return self.func(*args, **kwargs)
  File "/usr/local/lib/python3.10/site-packages/airflow/models/baseoperator.py", line 424, in wrapper
    return func(self, *args, **kwargs)
  File "/usr/local/lib/python3.10/site-packages/airflow/operators/python.py", line 238, in execute
    return_value = self.execute_callable()
  File "/usr/local/lib/python3.10/site-packages/airflow/operators/python.py", line 256, in execute_callable
    return runner.run(*self.op_args, **self.op_kwargs)
  File "/usr/local/lib/python3.10/site-packages/airflow/utils/operator_helpers.py", line 252, in run
    return self.func(*args, **kwargs)
  File "/app/src/command/manage_buckets.py", line 69, in process_to_curated
    processed_data = aws_s3.process_data(
AttributeError: 'AwsS3Repository' object has no attribute 'process_data'
[2025-03-12T21:28:51.561+0000] {taskinstance.py:1226} INFO - Marking task as FAILED. dag_id=data_lake_pipeline, task_id=transform_staging_to_curated, run_id=manual__2025-03-12T21:17:19.069606+00:00, execution_date=20250312T211719, start_date=20250312T212851, end_date=20250312T212851
[2025-03-12T21:28:51.609+0000] {taskinstance.py:341} INFO - ::group::Post task execution logs
[2025-03-12T21:28:51.610+0000] {standard_task_runner.py:124} ERROR - Failed to execute job 49 for task transform_staging_to_curated ('AwsS3Repository' object has no attribute 'process_data'; 173)
Traceback (most recent call last):
  File "/usr/local/lib/python3.10/site-packages/airflow/task/task_runner/standard_task_runner.py", line 117, in _start_by_fork
    ret = args.func(args, dag=self.dag)
  File "/usr/local/lib/python3.10/site-packages/airflow/cli/cli_config.py", line 49, in command
    return func(*args, **kwargs)
  File "/usr/local/lib/python3.10/site-packages/airflow/utils/cli.py", line 116, in wrapper
    return f(*args, **kwargs)
  File "/usr/local/lib/python3.10/site-packages/airflow/cli/commands/task_command.py", line 483, in task_run
    task_return_code = _run_task_by_selected_method(args, _dag, ti)
  File "/usr/local/lib/python3.10/site-packages/airflow/cli/commands/task_command.py", line 256, in _run_task_by_selected_method
    return _run_raw_task(args, ti)
  File "/usr/local/lib/python3.10/site-packages/airflow/cli/commands/task_command.py", line 341, in _run_raw_task
    return ti._run_raw_task(
  File "/usr/local/lib/python3.10/site-packages/airflow/utils/session.py", line 97, in wrapper
    return func(*args, session=session, **kwargs)
  File "/usr/local/lib/python3.10/site-packages/airflow/models/taskinstance.py", line 3006, in _run_raw_task
    return _run_raw_task(
  File "/usr/local/lib/python3.10/site-packages/airflow/models/taskinstance.py", line 274, in _run_raw_task
    TaskInstance._execute_task_with_callbacks(
  File "/usr/local/lib/python3.10/site-packages/airflow/models/taskinstance.py", line 3161, in _execute_task_with_callbacks
    result = self._execute_task(context, task_orig)
  File "/usr/local/lib/python3.10/site-packages/airflow/models/taskinstance.py", line 3185, in _execute_task
    return _execute_task(self, context, task_orig)
  File "/usr/local/lib/python3.10/site-packages/airflow/models/taskinstance.py", line 768, in _execute_task
    result = _execute_callable(context=context, **execute_callable_kwargs)
  File "/usr/local/lib/python3.10/site-packages/airflow/models/taskinstance.py", line 734, in _execute_callable
    return ExecutionCallableRunner(
  File "/usr/local/lib/python3.10/site-packages/airflow/utils/operator_helpers.py", line 252, in run
    return self.func(*args, **kwargs)
  File "/usr/local/lib/python3.10/site-packages/airflow/models/baseoperator.py", line 424, in wrapper
    return func(self, *args, **kwargs)
  File "/usr/local/lib/python3.10/site-packages/airflow/operators/python.py", line 238, in execute
    return_value = self.execute_callable()
  File "/usr/local/lib/python3.10/site-packages/airflow/operators/python.py", line 256, in execute_callable
    return runner.run(*self.op_args, **self.op_kwargs)
  File "/usr/local/lib/python3.10/site-packages/airflow/utils/operator_helpers.py", line 252, in run
    return self.func(*args, **kwargs)
  File "/app/src/command/manage_buckets.py", line 69, in process_to_curated
    processed_data = aws_s3.process_data(
AttributeError: 'AwsS3Repository' object has no attribute 'process_data'
[2025-03-12T21:28:51.646+0000] {local_task_job_runner.py:266} INFO - Task exited with return code 1
[2025-03-12T21:28:51.683+0000] {taskinstance.py:3901} INFO - 0 downstream tasks scheduled from follow-on schedule check
[2025-03-12T21:28:51.693+0000] {local_task_job_runner.py:245} INFO - ::endgroup::
