[2025-03-12T16:35:02.892+0000] {local_task_job_runner.py:123} INFO - ::group::Pre task execution logs
[2025-03-12T16:35:02.921+0000] {taskinstance.py:2614} INFO - Dependencies all met for dep_context=non-requeueable deps ti=<TaskInstance: data_lake_pipeline.process_to_raw manual__2025-03-12T16:34:57.709677+00:00 [queued]>
[2025-03-12T16:35:02.932+0000] {taskinstance.py:2614} INFO - Dependencies all met for dep_context=requeueable deps ti=<TaskInstance: data_lake_pipeline.process_to_raw manual__2025-03-12T16:34:57.709677+00:00 [queued]>
[2025-03-12T16:35:02.933+0000] {taskinstance.py:2867} INFO - Starting attempt 1 of 2
[2025-03-12T16:35:02.972+0000] {taskinstance.py:2890} INFO - Executing <Task(PythonOperator): process_to_raw> on 2025-03-12 16:34:57.709677+00:00
[2025-03-12T16:35:02.980+0000] {standard_task_runner.py:72} INFO - Started process 294 to run task
[2025-03-12T16:35:02.984+0000] {standard_task_runner.py:104} INFO - Running: ['***', 'tasks', 'run', 'data_lake_pipeline', 'process_to_raw', 'manual__2025-03-12T16:34:57.709677+00:00', '--job-id', '23', '--raw', '--subdir', 'DAGS_FOLDER/data_pipeline_dag.py', '--cfg-path', '/tmp/tmpy4n4a3dr']
[2025-03-12T16:35:02.987+0000] {standard_task_runner.py:105} INFO - Job 23: Subtask process_to_raw
[2025-03-12T16:35:03.004+0000] {logging_mixin.py:190} WARNING - /usr/local/lib/python3.10/site-packages/***/settings.py:209 DeprecationWarning: The sql_alchemy_conn option in [core] has been moved to the sql_alchemy_conn option in [database] - the old setting has been used, but please update your config.
[2025-03-12T16:35:03.036+0000] {task_command.py:467} INFO - Running <TaskInstance: data_lake_pipeline.process_to_raw manual__2025-03-12T16:34:57.709677+00:00 [running]> on host ***-scheduler
[2025-03-12T16:35:03.113+0000] {taskinstance.py:3134} INFO - Exporting env vars: AIRFLOW_CTX_DAG_OWNER='***' AIRFLOW_CTX_DAG_ID='data_lake_pipeline' AIRFLOW_CTX_TASK_ID='process_to_raw' AIRFLOW_CTX_EXECUTION_DATE='2025-03-12T16:34:57.709677+00:00' AIRFLOW_CTX_TRY_NUMBER='1' AIRFLOW_CTX_DAG_RUN_ID='manual__2025-03-12T16:34:57.709677+00:00'
[2025-03-12T16:35:03.114+0000] {taskinstance.py:732} INFO - ::endgroup::
[2025-03-12T16:35:03.127+0000] {manage_buckets.py:22} INFO - [Data manager] Downloading data from HuggingFace...
[2025-03-12T16:36:11.686+0000] {taskinstance.py:3313} ERROR - Task failed with exception
Traceback (most recent call last):
  File "/usr/local/lib/python3.10/site-packages/airflow/models/taskinstance.py", line 768, in _execute_task
    result = _execute_callable(context=context, **execute_callable_kwargs)
  File "/usr/local/lib/python3.10/site-packages/airflow/models/taskinstance.py", line 734, in _execute_callable
    return ExecutionCallableRunner(
  File "/usr/local/lib/python3.10/site-packages/airflow/utils/operator_helpers.py", line 252, in run
    return self.func(*args, **kwargs)
  File "/usr/local/lib/python3.10/site-packages/airflow/models/baseoperator.py", line 424, in wrapper
    return func(self, *args, **kwargs)
  File "/usr/local/lib/python3.10/site-packages/airflow/operators/python.py", line 238, in execute
    return_value = self.execute_callable()
  File "/usr/local/lib/python3.10/site-packages/airflow/operators/python.py", line 256, in execute_callable
    return runner.run(*self.op_args, **self.op_kwargs)
  File "/usr/local/lib/python3.10/site-packages/airflow/utils/operator_helpers.py", line 252, in run
    return self.func(*args, **kwargs)
  File "/app/src/command/manage_buckets.py", line 23, in ingest_data
    data = load_dataset(repo, dataset_name)
  File "/usr/local/lib/python3.10/site-packages/datasets/load.py", line 2129, in load_dataset
    builder_instance = load_dataset_builder(
  File "/usr/local/lib/python3.10/site-packages/datasets/load.py", line 1849, in load_dataset_builder
    dataset_module = dataset_module_factory(
  File "/usr/local/lib/python3.10/site-packages/datasets/load.py", line 1731, in dataset_module_factory
    raise e1 from None
  File "/usr/local/lib/python3.10/site-packages/datasets/load.py", line 1696, in dataset_module_factory
    ).get_module()
  File "/usr/local/lib/python3.10/site-packages/datasets/load.py", line 1073, in get_module
    module_name, default_builder_kwargs = infer_module_for_data_files(
  File "/usr/local/lib/python3.10/site-packages/datasets/load.py", line 601, in infer_module_for_data_files
    raise ValueError(f"Couldn't infer the same data file format for all splits. Got {split_modules}")
ValueError: Couldn't infer the same data file format for all splits. Got {'test': (None, {}), 'train': ('parquet', {}), 'validation': ('parquet', {})}
[2025-03-12T16:36:11.710+0000] {taskinstance.py:1226} INFO - Marking task as UP_FOR_RETRY. dag_id=data_lake_pipeline, task_id=process_to_raw, run_id=manual__2025-03-12T16:34:57.709677+00:00, execution_date=20250312T163457, start_date=20250312T163502, end_date=20250312T163611
[2025-03-12T16:36:11.741+0000] {taskinstance.py:341} INFO - ::group::Post task execution logs
[2025-03-12T16:36:11.742+0000] {standard_task_runner.py:124} ERROR - Failed to execute job 23 for task process_to_raw (Couldn't infer the same data file format for all splits. Got {'test': (None, {}), 'train': ('parquet', {}), 'validation': ('parquet', {})}; 294)
Traceback (most recent call last):
  File "/usr/local/lib/python3.10/site-packages/airflow/task/task_runner/standard_task_runner.py", line 117, in _start_by_fork
    ret = args.func(args, dag=self.dag)
  File "/usr/local/lib/python3.10/site-packages/airflow/cli/cli_config.py", line 49, in command
    return func(*args, **kwargs)
  File "/usr/local/lib/python3.10/site-packages/airflow/utils/cli.py", line 116, in wrapper
    return f(*args, **kwargs)
  File "/usr/local/lib/python3.10/site-packages/airflow/cli/commands/task_command.py", line 483, in task_run
    task_return_code = _run_task_by_selected_method(args, _dag, ti)
  File "/usr/local/lib/python3.10/site-packages/airflow/cli/commands/task_command.py", line 256, in _run_task_by_selected_method
    return _run_raw_task(args, ti)
  File "/usr/local/lib/python3.10/site-packages/airflow/cli/commands/task_command.py", line 341, in _run_raw_task
    return ti._run_raw_task(
  File "/usr/local/lib/python3.10/site-packages/airflow/utils/session.py", line 97, in wrapper
    return func(*args, session=session, **kwargs)
  File "/usr/local/lib/python3.10/site-packages/airflow/models/taskinstance.py", line 3006, in _run_raw_task
    return _run_raw_task(
  File "/usr/local/lib/python3.10/site-packages/airflow/models/taskinstance.py", line 274, in _run_raw_task
    TaskInstance._execute_task_with_callbacks(
  File "/usr/local/lib/python3.10/site-packages/airflow/models/taskinstance.py", line 3161, in _execute_task_with_callbacks
    result = self._execute_task(context, task_orig)
  File "/usr/local/lib/python3.10/site-packages/airflow/models/taskinstance.py", line 3185, in _execute_task
    return _execute_task(self, context, task_orig)
  File "/usr/local/lib/python3.10/site-packages/airflow/models/taskinstance.py", line 768, in _execute_task
    result = _execute_callable(context=context, **execute_callable_kwargs)
  File "/usr/local/lib/python3.10/site-packages/airflow/models/taskinstance.py", line 734, in _execute_callable
    return ExecutionCallableRunner(
  File "/usr/local/lib/python3.10/site-packages/airflow/utils/operator_helpers.py", line 252, in run
    return self.func(*args, **kwargs)
  File "/usr/local/lib/python3.10/site-packages/airflow/models/baseoperator.py", line 424, in wrapper
    return func(self, *args, **kwargs)
  File "/usr/local/lib/python3.10/site-packages/airflow/operators/python.py", line 238, in execute
    return_value = self.execute_callable()
  File "/usr/local/lib/python3.10/site-packages/airflow/operators/python.py", line 256, in execute_callable
    return runner.run(*self.op_args, **self.op_kwargs)
  File "/usr/local/lib/python3.10/site-packages/airflow/utils/operator_helpers.py", line 252, in run
    return self.func(*args, **kwargs)
  File "/app/src/command/manage_buckets.py", line 23, in ingest_data
    data = load_dataset(repo, dataset_name)
  File "/usr/local/lib/python3.10/site-packages/datasets/load.py", line 2129, in load_dataset
    builder_instance = load_dataset_builder(
  File "/usr/local/lib/python3.10/site-packages/datasets/load.py", line 1849, in load_dataset_builder
    dataset_module = dataset_module_factory(
  File "/usr/local/lib/python3.10/site-packages/datasets/load.py", line 1731, in dataset_module_factory
    raise e1 from None
  File "/usr/local/lib/python3.10/site-packages/datasets/load.py", line 1696, in dataset_module_factory
    ).get_module()
  File "/usr/local/lib/python3.10/site-packages/datasets/load.py", line 1073, in get_module
    module_name, default_builder_kwargs = infer_module_for_data_files(
  File "/usr/local/lib/python3.10/site-packages/datasets/load.py", line 601, in infer_module_for_data_files
    raise ValueError(f"Couldn't infer the same data file format for all splits. Got {split_modules}")
ValueError: Couldn't infer the same data file format for all splits. Got {'test': (None, {}), 'train': ('parquet', {}), 'validation': ('parquet', {})}
[2025-03-12T16:36:11.787+0000] {local_task_job_runner.py:266} INFO - Task exited with return code 1
[2025-03-12T16:36:11.815+0000] {taskinstance.py:3901} INFO - 0 downstream tasks scheduled from follow-on schedule check
[2025-03-12T16:36:11.820+0000] {local_task_job_runner.py:245} INFO - ::endgroup::
