[2025-03-12T13:26:33.853+0000] {local_task_job_runner.py:123} INFO - ::group::Pre task execution logs
[2025-03-12T13:26:33.881+0000] {taskinstance.py:2614} INFO - Dependencies all met for dep_context=non-requeueable deps ti=<TaskInstance: data_lake_pipeline.process_to_raw manual__2025-03-12T13:26:27.288859+00:00 [queued]>
[2025-03-12T13:26:33.894+0000] {taskinstance.py:2614} INFO - Dependencies all met for dep_context=requeueable deps ti=<TaskInstance: data_lake_pipeline.process_to_raw manual__2025-03-12T13:26:27.288859+00:00 [queued]>
[2025-03-12T13:26:33.895+0000] {taskinstance.py:2867} INFO - Starting attempt 1 of 2
[2025-03-12T13:26:33.935+0000] {taskinstance.py:2890} INFO - Executing <Task(PythonOperator): process_to_raw> on 2025-03-12 13:26:27.288859+00:00
[2025-03-12T13:26:33.941+0000] {standard_task_runner.py:72} INFO - Started process 219 to run task
[2025-03-12T13:26:33.945+0000] {standard_task_runner.py:104} INFO - Running: ['***', 'tasks', 'run', 'data_lake_pipeline', 'process_to_raw', 'manual__2025-03-12T13:26:27.288859+00:00', '--job-id', '42', '--raw', '--subdir', 'DAGS_FOLDER/data_pipeline_dag.py', '--cfg-path', '/tmp/tmpxopphxbl']
[2025-03-12T13:26:33.949+0000] {standard_task_runner.py:105} INFO - Job 42: Subtask process_to_raw
[2025-03-12T13:26:33.975+0000] {logging_mixin.py:190} WARNING - /usr/local/lib/python3.10/site-packages/***/settings.py:209 DeprecationWarning: The sql_alchemy_conn option in [core] has been moved to the sql_alchemy_conn option in [database] - the old setting has been used, but please update your config.
[2025-03-12T13:26:34.021+0000] {task_command.py:467} INFO - Running <TaskInstance: data_lake_pipeline.process_to_raw manual__2025-03-12T13:26:27.288859+00:00 [running]> on host ***-scheduler
[2025-03-12T13:26:34.128+0000] {taskinstance.py:3134} INFO - Exporting env vars: AIRFLOW_CTX_DAG_OWNER='***' AIRFLOW_CTX_DAG_ID='data_lake_pipeline' AIRFLOW_CTX_TASK_ID='process_to_raw' AIRFLOW_CTX_EXECUTION_DATE='2025-03-12T13:26:27.288859+00:00' AIRFLOW_CTX_TRY_NUMBER='1' AIRFLOW_CTX_DAG_RUN_ID='manual__2025-03-12T13:26:27.288859+00:00'
[2025-03-12T13:26:34.130+0000] {taskinstance.py:732} INFO - ::endgroup::
[2025-03-12T13:26:34.143+0000] {manage_buckets.py:19} INFO - [Data manager] Downloading data from HuggingFace...
[2025-03-12T13:26:42.268+0000] {logging_mixin.py:190} WARNING - Generating test split:   0%|          | 0/4358 [00:00<?, ? examples/s]
[2025-03-12T13:26:42.292+0000] {logging_mixin.py:190} WARNING - Generating test split: 100%|##########| 4358/4358 [00:00<00:00, 182128.46 examples/s]
[2025-03-12T13:26:42.293+0000] {logging_mixin.py:190} WARNING - Generating train split:   0%|          | 0/36718 [00:00<?, ? examples/s]
[2025-03-12T13:26:42.372+0000] {logging_mixin.py:190} WARNING - Generating train split: 100%|##########| 36718/36718 [00:00<00:00, 466983.40 examples/s]
[2025-03-12T13:26:42.373+0000] {logging_mixin.py:190} WARNING - Generating validation split:   0%|          | 0/3760 [00:00<?, ? examples/s]
[2025-03-12T13:26:42.390+0000] {logging_mixin.py:190} WARNING - Generating validation split: 100%|##########| 3760/3760 [00:00<00:00, 241077.75 examples/s]
[2025-03-12T13:26:42.413+0000] {manage_buckets.py:22} INFO - [Data manager] Data successfully downloaded.
[2025-03-12T13:26:42.414+0000] {manage_buckets.py:25} INFO - [Data manager] Transferring data to S3 bucket...
[2025-03-12T13:26:42.415+0000] {aws_s3_repository.py:65} INFO - [AWS S3] ðŸš€ Uploading into raw ...
[2025-03-12T13:26:42.415+0000] {aws_s3_repository.py:68} INFO - [AWS S3] Transferring train data...
[2025-03-12T13:26:42.415+0000] {aws_s3_repository.py:69} INFO - [AWS S3] split_data: Dataset({
    features: ['text'],
    num_rows: 36718
})
[2025-03-12T13:26:42.519+0000] {aws_s3_repository.py:71} INFO - [AWS S3] Unit: 
[2025-03-12T13:26:42.521+0000] {aws_s3_repository.py:77} INFO - [AWS S3] Uploading ... to train/train_0.txt
[2025-03-12T13:26:51.256+0000] {aws_s3.py:36} CRITICAL - [S3 Client] Error : Could not connect to the endpoint URL: "http://localstack:4566/raw/train/train_0.txt"
[2025-03-12T13:26:51.271+0000] {aws_s3_repository.py:82} CRITICAL - [AWS S3] Error while uploading data into raw ...
[2025-03-12T13:26:51.272+0000] {manage_buckets.py:37} CRITICAL - [Data manager] Error during uploading files to S3 bucket named raw
[2025-03-12T13:26:51.272+0000] {python.py:240} INFO - Done. Returned value was: None
[2025-03-12T13:26:51.280+0000] {taskinstance.py:341} INFO - ::group::Post task execution logs
[2025-03-12T13:26:51.281+0000] {taskinstance.py:353} INFO - Marking task as SUCCESS. dag_id=data_lake_pipeline, task_id=process_to_raw, run_id=manual__2025-03-12T13:26:27.288859+00:00, execution_date=20250312T132627, start_date=20250312T132633, end_date=20250312T132651
[2025-03-12T13:26:51.369+0000] {local_task_job_runner.py:266} INFO - Task exited with return code 0
[2025-03-12T13:26:51.376+0000] {local_task_job_runner.py:245} INFO - ::endgroup::
